Workbook

Sheet Portaria
E5: SISTEMA DE CONSULTA DE ACESSO - PORTARIA (BOUGAINVILLE)
E7: DIGITE O LOTE-QUADRA
J9: 22-28
E13: STATUS DE ACESSO
E14: =IF(J9="","",IF(COUNTIF('Lote Entregues'!$C$6:$C$4500,J9)=0,"LOTE NÃO ENCONTRADO - CONSULTAR ADMINISTRAÇÃO",IF(COUNTIF('Lote Entregues'!$J$6:$J$4500,J9)>0,IF(COUNTIFS(Embargos!$D$3:$D$4484,J9,Embargos!$C$3:$C$4484,"SIM")>0,"LIBERADO - MORADOR","EMBARGADO - NÃO LIBERAR"),"LIBERADO")))
E16: =IF(J9="","",IF(COUNTIF('Lote Entregues'!$C$6:$C$4500,J9)=0,"NÃO IDENTIFICADO",IF(COUNTIF('Lote Entregues'!$J$6:$J$4500,J9)>0,IF(COUNTIFS(Embargos!$D$3:$D$4484,J9,Embargos!$C$3:$C$4484,"SIM")>0,"MORADOR - ACESSO PERMITIDO","NÃO É MORADOR - ACESSO RESTRITO"),IF(IFERROR(VLOOKUP(J9,'Lote Entregues'!C6:G4500,5,FALSE),"NÃO")="SIM","MORADOR","NÃO É MORADOR"))))

Sheet Lote Entregues
B3: ATUALIZADO - 23/09/2026
B4: LISTA DE LOTES ENTREGUES - BOUGAINVILLLE
B5: QUANTIDADES ENTREGUES | C5: LOTE - QUADRA | D5: LOTE | E5: QUADRA | F5: PROPRIETÁRIO | G5: MORADOR | H5: DATA DA ENTREGA | I5: SETOR | J5: ANALISE | K5: SITUAÇÃO
B6: 1 | C6: 19-76 | D6: 19 | E6: 76 | F6: A ENGENHARIA DO FRIO EIRELI | H6: 46030 | I6: ROXO | J6: =IFERROR(VLOOKUP($C6,Embargos!$D$3:$D$4484,1,FALSE), "OK") | K6: =IF(J6=C6, "EMBARGADO", "LIBERADO")
B7: 2 | C7: 7-26 | D7: 7 | E7: 26 | F7: ADAILSON OLIVEIRA DA SILVA | H7: 44960 | I7: VERMELHO | J7: =IFERROR(VLOOKUP($C7,Embargos!$D$3:$D$4484,1,FALSE), "OK") | K7: =IF(J7=C7, "EMBARGADO", "LIBERADO")
B8: 3 | C8: 46-69 | D8: 46 | E8: 69 | F8: ADAILSON SILVA DOS SANTOS | H8: 44944 | I8: AMARELO | J8: =IFERROR(VLOOKUP($C8,Embargos!$D$3:$D$4484,1,FALSE), "OK") | K8: =IF(J8=C8, "EMBARGADO", "LIBERADO")
B9: 4 | C9: 1-52 | D9: 1 | E9: 52 | F9: ADALBERTO PAIVA SILVA FILHO | H9: 44942 | I9: AMARELO | J9: =IFERROR(VLOOKUP($C9,Embargos!$D$3:$D$4484,1,FALSE), "OK") | K9: =IF(J9=C9, "EMBARGADO", "LIBERADO")
B10: 5 | C10: 30-19 | D10: 30 | E10: 19 | F10: ADAM TAVARES MAGALHAES | H10: 46175 | I10: EXCLUSIVE | J10: =IFERROR(VLOOKUP($C10,Embargos!$D$3:$D$4484,1,FALSE), "OK") | K10: =IF(J10=C10, "EMBARGADO", "LIBERADO")
B11: 6 | C11: 29-24 | D11: 29 | E11: 24 | F11: ADAM TAVARES MAGALHAES | H11: 46175 | I11: VERMELHO | J11: =IFERROR(VLOOKUP($C11,Embargos!$D$3:$D$4484,1,FALSE), "OK") | K11: =IF(J11=C11, "EMBARGADO", "LIBERADO")
B12: 7 | C12: 8-19 | D12: 8 | E12: 19 | F12: ADAM TAVARES MAGALHAES | H12: 46175 | I12: EXCLUSIVE | J12: =IFERROR(VLOOKUP($C12,Embargos!$D$3:$D$4484,1,FALSE), "OK") | K12: =IF(J12=C12, "EMBARGADO", "LIBERADO")
B13: 8 | C13: 8-46 | D13: 8 | E13: 46 | F13: ADELE SUZANA DO CARMO TAVARES | H13: 46265 | I13: LARANJA | J13: =IFERROR(VLOOKUP($C13,Embargos!$D$3:$D$4484,1,FALSE), "OK") | K13: =IF(J13=C13, "EMBARGADO", "LIBERADO")
B14: 9 | C14: 33-14 | D14: 33 | E14: 14 | F14: ADEMIR GONCALVES CORREA JUNIOR | H14: 45262 | I14: GARDEN | J14: =IFERROR(VLOOKUP($C14,Embargos!$D$3:$D$4484,1,FALSE), "OK") | K14: =IF(J14=C14, "EMBARGADO", "LIBERADO")
B15: 10 | C15: 34-14 | D15: 34 | E15: 14 | F15: ADEMIR GONCALVES CORREA JUNIOR | H15: 45262 | I15: GARDEN | J15: =IFERROR(VLOOKUP($C15,Embargos!$D$3:$D$4484,1,FALSE), "OK") | K15: =IF(J15=C15, "EMBARGADO", "LIBERADO")
B16: 11 | C16: 24-16 | D16: 24 | E16: 16 | F16: ADENARD FRANCISCO CLEOPHAS CUNHA | H16: 46165 | I16: LARANJA | J16: =IFERROR(VLOOKUP($C16,Embargos!$D$3:$D$4484,1,FALSE), "OK") | K16: =IF(J16=C16, "EMBARGADO", "LIBERADO")
B17: 12 | C17: 18-29 | D17: 18 | E17: 29 | F17: ADERSON PESSOA BARRETO | H17: 44965 | I17: VERMELHO | J17: =IFERROR(VLOOKUP($C17,Embargos!$D$3:$D$4484,1,FALSE), "OK") | K17: =IF(J17=C17, "EMBARGADO", "LIBERADO")
B18: 13 | C18: 20-67 | D18: 20 | E18: 67 | F18: ADILSON OLIVEIRA COSTA JUNIOR | H18: 44952 | I18: AMARELO | J18: =IFERROR(VLOOKUP($C18,Embargos!$D$3:$D$4484,1,FALSE), "OK") | K18: =IF(J18=C18, "EMBARGADO", "LIBERADO")
... B96: 91 | C96: 4-53 | D96: 4 | E96: 53 | F96: ALLAN LAKISE RAMOS | H96: 45300 | I96: AMARELO | J96: =IFERROR(VLOOKUP($C96,Embargos!$D$3:$D$4484,1,FALSE), "OK") | K96: =IF(J96=C96, "EMBARGADO", "LIBERADO")
B97: 92 | C97: 41-75 | D97: 41 | E97: 75 | F97: ALLOF THAYRO SOUZA PALHANO | G97: SIM | H97: 45199 | I97: ROXO | J97: =IFERROR(VLOOKUP($C97,Embargos!$D$3:$D$4484,1,FALSE), "OK") | K97: =IF(J97=C97, "EMBARGADO", "LIBERADO")
B98: 93 | C98: 9-50 | D98: 9 | E98: 50 | F98: ALLYSON LUIZ DA SILVA DUARTE | H98: 46031 | I98: AMARELO | J98: =IFERROR(VLOOKUP($C98,Embargos!$D$3:$D$4484,1,FALSE), "OK") | K98: =IF(J98=C98, "EMBARGADO", "LIBERADO")
B99: 94 | C99: 37-38 | D99: 37 | E99: 38 | F99: ALMIR RODRIGO PINTO DE OLIVEIRA | H99: 46056 | I99: LARANJA | J99: =IFERROR(VLOOKUP($C99,Embargos!$D$3:$D$4484,1,FALSE), "OK") | K99: =IF(J99=C99, "EMBARGADO", "LIBERADO")
B100: 95 | C100: 31-13 | D100: 31 | E100: 13 | F100: ALMIR SALES RODRIGUES | H100: 45477 | I100: GARDEN | J100: =IFERROR(VLOOKUP($C100,Embargos!$D$3:$D$4484,1,FALSE), "OK") | K100: =IF(J100=C100, "EMBARGADO", "LIBERADO")
B101: 96 | C101: 34-9 | D101: 34 | E101: 9 | F101: ALONSO JUNIOR PINHEIRO CARVALHO | H101: 45257 | I101: GARDEN | J101: =IFERROR(VLOOKUP($C101,Embargos!$D$3:$D$4484,1,FALSE), "OK") | K101: =IF(J101=C101, "EMBARGADO", "LIBERADO")
B102: 97 | C102: 14-63 | D102: 14 | E102: 63 | F102: ALTERLINE RODRIGUES DA SILVA | H102: 45867 | I102: ROXO | J102: =IFERROR(VLOOKUP($C102,Embargos!$D$3:$D$4484,1,FALSE), "OK") | K102: =IF(J102=C102, "EMBARGADO", "LIBERADO")
B103: 98 | C103: 11-18 | D103: 11 | E103: 18 | F103: ALTINO AYRES DA COSTA JUNIOR | H103: 45978 | I103: EXCLUSIVE | J103: =IFERROR(VLOOKUP($C103,Embargos!$D$3:$D$4484,1,FALSE), "OK") | K103: =IF(J103=C103, "EMBARGADO", "LIBERADO")
B104: 99 | C104: 22-7 | D104: 22 | E104: 7 | F104: ALUIZIO RODRIGUES DO CARMO FILHO | H104: 45260 | I104: GARDEN | J104: =IFERROR(VLOOKUP($C104,Embargos!$D$3:$D$4484,1,FALSE), "OK") | K104: =IF(J104=C104, "EMBARGADO", "LIBERADO")
B105: 100 | C105: 52-36 | D105: 52 | E105: 36 | F105: ALVARO DALLBELLO | H105: 44949 | I105: LARANJA | J105: =IFERROR(VLOOKUP($C105,Embargos!$D$3:$D$4484,1,FALSE), "OK") | K105: =IF(J105=C105, "EMBARGADO", "LIBERADO")
B106: 101 | C106: 23-10 | D106: 23 | E106: 10 | F106: AMANDA BIANCHINI PEPER | H106: 45346 | I106: GARDEN | J106: =IFERROR(VLOOKUP($C106,Embargos!$D$3:$D$4484,1,FALSE), "OK") | K106: =IF(J106=C106, "EMBARGADO", "LIBERADO")
B107: 102 | C107: 56-75 | D107: 56 | E107: 75 | F107: AMANDA DO SOCORRO CUNHA LACERDA | H107: 45227 | I107: ROXO | J107: =IFERROR(VLOOKUP($C107,Embargos!$D$3:$D$4484,1,FALSE), "OK") | K107: =IF(J107=C107, "EMBARGADO", "LIBERADO")
B108: 103 | C108: 33-5 | D108: 33 | E108: 5 | F108: AMANDA FONTELLES ALVES | H108: 45554 | I108: GARDEN | J108: =IFERROR(VLOOKUP($C108,Embargos!$D$3:$D$4484,1,FALSE), "OK") | K108: =IF(J108=C108, "EMBARGADO", "LIBERADO")
B109: 104 | C109: 34-5 | D109: 34 | E109: 5 | F109: AMANDA FONTELLES ALVES | H109: 45573 | I109: GARDEN | J109: =IFERROR(VLOOKUP($C109,Embargos!$D$3:$D$4484,1,FALSE), "OK") | K109: =IF(J109=C109, "EMBARGADO", "LIBERADO")
... B121: 116 | C121: 9-7 | D121: 9 | E121: 7 | F121: ANA CAROLINA VIEGAS DO ROSARIO | H121: 45260 | I121: GARDEN | J121: =IFERROR(VLOOKUP($C121,Embargos!$D$3:$D$4484,1,FALSE), "OK") | K121: =IF(J121=C121, "EMBARGADO", "LIBERADO")
B122: 117 | C122: 58-75 | D122: 58 | E122: 75 | F122: ANA CELIA MONTEIRO DE SOUZA PEREIRA | G122: SIM | H122: 45213 | I122: ROXO | J122: =IFERROR(VLOOKUP($C122,Embargos!$D$3:$D$4484,1,FALSE), "OK") | K122: =IF(J122=C122, "EMBARGADO", "LIBERADO")
B123: 118 | C123: 45-60 | D123: 45 | E123: 60 | F123: ANA CELIA MONTEIRO DE SOUZA PEREIRA | H123: 45680 | I123: ROXO | J123: =IFERROR(VLOOKUP($C123,Embargos!$D$3:$D$4484,1,FALSE), "OK") | K123: =IF(J123=C123, "EMBARGADO", "LIBERADO")
B124: 119 | C124: 14-4 | D124: 14 | E124: 4 | F124: ANA CLARA POMPEU MENEZES | H124: 45374 | I124: GARDEN | J124: =IFERROR(VLOOKUP($C124,Embargos!$D$3:$D$4484,1,FALSE), "OK") | K124: =IF(J124=C124, "EMBARGADO", "LIBERADO")
B125: 120 | C125: 15-69 | D125: 15 | E125: 69 | F125: ANA CLAUDIA FARIA CAMARGO | H125: 45096 | I125: AMARELO | J125: =IFERROR(VLOOKUP($C125,Embargos!$D$3:$D$4484,1,FALSE), "OK") | K125: =IF(J125=C125, "EMBARGADO", "LIBERADO")
B126: 121 | C126: 14-47 | D126: 14 | E126: 47 | F126: ANA CLAUDIA VENUTO DE ALFAIA | H126: 44968 | I126: AMARELO | J126: =IFERROR(VLOOKUP($C126,Embargos!$D$3:$D$4484,1,FALSE), "OK") | K126: =IF(J126=C126, "EMBARGADO", "LIBERADO")
B127: 122 | C127: 15-12 | D127: 15 | E127: 12 | F127: ANA CLAUDIA WANZELER MARCAL CARVALHO | H127: 45740 | I127: GARDEN | J127: =IFERROR(VLOOKUP($C127,Embargos!$D$3:$D$4484,1,FALSE), "OK") | K127: =IF(J127=C127, "EMBARGADO", "LIBERADO")
B128: 123 | C128: 15-58 | D128: 15 | E128: 58 | F128: ANA CLEA DA SILVA NASCIMENTO | H128: 45229 | I128: ROXO | J128: =IFERROR(VLOOKUP($C128,Embargos!$D$3:$D$4484,1,FALSE), "OK") | K128: =IF(J128=C128, "EMBARGADO", "LIBERADO")
B129: 124 | C129: 41-51 | D129: 41 | E129: 51 | F129: ANA CRISTINA CORREA MARTINS | H129: 45022 | I129: AMARELO | J129: =IFERROR(VLOOKUP($C129,Embargos!$D$3:$D$4484,1,FALSE), "OK") | K129: =IF(J129=C129, "EMBARGADO", "LIBERADO")
B130: 125 | C130: 14-12 | D130: 14 | E130: 12 | F130: ANA CRISTINA SANTOS SODRÉ | H130: 45272 | I130: GARDEN | J130: =IFERROR(VLOOKUP($C130,Embargos!$D$3:$D$4484,1,FALSE), "OK") | K130: =IF(J130=C130, "EMBARGADO", "LIBERADO")
...

Sheet Embargos
A1: Embargo de obra - 24.09.2026
A2: DIAS DE ATRASO | B2: Construção | C2: Habitado | D2: Lote/Quadra | E2: Nome do Cliente | F2: Atraso desde
A3: 50 | B3: Sem construção | C3: NÃO | D3: 19-62 | E3: ADRIANA DE ALCANTARA SIQUEIRA | F3: 46150
A4: 221 | B4: Sem construção | C4: NÃO | D4: 18-30 | E4: AGRIGEO TOPOGRAFIA E SERVIÇO EIRELI | F4: 15/02/2026
A5: 50 | B5: Sem construção | C5: NÃO | D5: 13-12 | E5: AGUINALDO LUIZ DOS REIS SILVA JUNIOR | F5: 46150
A6: 40 | B6: BARRACÃO DE OBRA | C6: NÃO | D6: 60-51 | E6: ALAN MARCELO LOBATO CHAGAS | F6: 15/08/2026
A7: 19 | B7: CASA / RESIDÊNCIA | C7: NÃO | D7: 37-6 | E7: ALAN MORAES VIANA | F7: 46151
A8: 71 | B8: Sem construção | C8: NÃO | D8: 4-3 | E8: ALCI COSTA PENA | F8: 15/07/2026
A9: 40 | B9: Sem construção | C9: NÃO | D9: 5-77 | E9: ALDO LOBO MELO | F9: 15/08/2026
A10: 40 | B10: Sem construção | C10: NÃO | D10: 13-15 | E10: ALESSANDRA SACRAMENTO COSTA | F10: 15/08/2026
A11: 19 | B11: Sem construção | C11: NÃO | D11: 47-69 | E11: ALIANNE LUCIA DE ALMEIDA MATOS | F11: 46151
A12: 66 | B12: Sem construção | C12: NÃO | D12: 4-54 | E12: ALINE ELLEN FONTES DA COSTA | F12: 20/07/2026
A13: 19 | B13: Sem construção | C13: NÃO | D13: 34-9 | E13: ALONSO JUNIOR PINHEIRO CARVALHO | F13: 46151
A14: 45 | B14: Sem construção | C14: NÃO | D14: 11-18 | E14: ALTINO AYRES DA COSTA JUNIOR | F14: 46303
A15: 14 | B15: Sem construção | C15: NÃO | D15: 5-26 | E15: AMANDA VITORIA DA SILVA SOUZA | F15: 46304
A16: 50 | B16: Sem construção | C16: NÃO | D16: 28-48 | E16: AMELIA DAS GRAÇAS CANTÃO SIMÕES | F16: 46150
A17: 19 | B17: Sem construção | C17: NÃO | D17: 10-57 | E17: ANA CAROLINA SOARES LAUANDE | F17: 46151
A18: 35 | B18: Sem construção | C18: NÃO | D18: 17-45 | E18: ANA PAULA SILVA DOS SANTOS | F18: 20/08/2026
A19: 231 | B19: Sem construção | C19: NÃO | D19: 20-55 | E19: ANA PRISCILA MONTEIRO NUNES | F19: 46144
A20: 127 | B20: Sem construção | C20: NÃO | D20: 30-18 | E20: ANA TATIANE COELHO REBELO | F20: 20/05/2026
A21: 40 | B21: Sem construção | C21: NÃO | D21: 23-38 | E21: ANA VALERIA RIBEIRO BORGES | F21: 15/08/2026
A22: 101 | B22: Sem construção | C22: NÃO | D22: 17-8 | E22: ANANDA MIRANDA LOPES | F22: 15/06/2026
A23: 19 | B23: Sem construção | C23: NÃO | D23: 23-51 | E23: ANDERSON RICARDO DA SILVA CABRAL | F23: 46151
A24: 50 | B24: Sem construção | C24: NÃO | D24: 5-5 | E24: ANDRE RODRIGUES PESSOA | F24: 46150
A25: 19 | B25: Sem construção | C25: NÃO | D25: 7-5 | E25: ANDREA BRABO DE JESUS NEVES | F25: 46151
A26: 19 | B26: Sem construção | C26: NÃO | D26: 33-13 | E26: ANDREZA LUSTOSA DE SOUZA | F26: 46151
A27: 172 | B27: Sem construção | C27: NÃO | D27: 12-19 | E27: ANTONILDO SILVA DA SILVA | F27: 46146
A28: 19 | B28: Sem construção | C28: NÃO | D28: 3-2 | E28: ANTONIO AUGUSTO FERREIRA DA MOTA | F28: 46151
A29: 19 | B29: Sem construção | C29: NÃO | D29: 20-33 | E29: ANTONIO AUGUSTO FERREIRA DA MOTA | F29: 46151
A30: 40 | B30: Sem construção | C30: NÃO | D30: 51-75 | E30: ANTONIO LUIZ FERNANDES NETO | F30: 15/08/2026
A31: 50 | B31: Sem construção | C31: NÃO | D31: 20-26 | E31: AYK EULALIA MOTTA SOUZA FREIRE | F31: 46150
A32: 71 | B32: Sem construção | C32: NÃO | D32: 14-33 | E32: BEATRIZ DE SOUZA DE SOUZA | F32: 15/07/2026
A33: 35 | B33: MURO | C33: NÃO | D33: 20-81 | E33: BENEDITO MARQUES RODRIGUES | F33: 20/08/2026
A34: 50 | B34: Sem construção | C34: NÃO | D34: 25-69 | E34: BETANIA CAROLAINE AGUIAR DE SOUZA | F34: 46150
A35: 45 | B35: Sem construção | C35: NÃO | D35: 47-35 | E35: BIANCA LAYANE GURJÃO DA COSTA | F35: 46303
A36: 45 | B36: Sem construção | C36: NÃO | D36: 11-66 | E36: BRENDA GONÇALVES DE ANDRADE PAES | F36: 46303
A37: 40 | B37: Sem construção | C37: NÃO | D37: 4-25 | E37: BRUNESA PAULA DE VASCONCELOS NOGUEIRA | F37: 15/08/2026
A38: 71 | B38: Sem construção | C38: NÃO | D38: 19-32 | E38: BRUNO ASSAYAG DA SILVA | F38: 15/07/2026
A39: 35 | B39: Sem construção | C39: NÃO | D39: 35-28 | E39: BRUNO FONSECA DE MEDEIROS | F39: 20/08/2026
A40: 35 | B40: Sem construção | C40: NÃO | D40: 28-78 | E40: BRUNO RAIOL MONTEIRO FERREIRA | F40: 20/08/2026
...
